Workbook

Sheet Total
A1: RESUMO DE CUSTO / RECEITAS E RESULTADOS POR CONVÊNIO - ANO 2025
A3: JANEIRO | G3: ="INTERNAÇÕES - "& '[1]intern. diaria convenio'!$C$42 | K3: ="DIÁRIAS - " &'[1]intern. diaria convenio'!$C$88
A4: CONVENIO | B4: Diárias por Leito | F4: MAT / MED | H4: DIARIAS | J4: TAXAS | L4: TOTAL_CUSTO | M4: TOTAL_VENDA | N4: TOTAL
B5: PRIV. | C5: SEMI-P | D5: UTI | E5: UCTI | F5: CUSTO | G5: VENDA | H5: CUSTO | I5: VENDA | J5: CUSTO | K5: VENDA | L5: CUSTO | M5: VENDA | N5: RESULTADO
A6: ACORDO | C6: 27 | F6: 11696.8 | H6: 13973.75 | J6: 48166.66 | L6: =F6+H6+J6 | M6: 72162.5 | N6: =M6-L6
A7: ACORDO JUDICIAL | C7: 32 | D7: 10 | F7: 15775.74 | H7: 13590 | J7: 16128.63 | L7: =F7+H7+J7 | M7: 1 | N7: =M7-L7
A8: ASSEFAZ | L8: =F8+H8+J8 | M8: =G8+I8+K8 | N8: =M8-L8
A9: C.M.I | C9: 9 | F9: 2591.63 | H9: 5030.55 | J9: 13694.47 | L9: =F9+H9+J9 | M9: 13 | N9: =M9-L9
A10: CABERGS | C10: 7 | F10: 228.03 | G10: 3278.68 | H10: 3912.65 | I10: 2190.13 | J10: 887.92 | K10: 1165.13 | L10: =F10+H10+J10 | M10: =SUM(G10,I10,K10) | N10: =M10-L10
A11: CAIXA ECONOMICA FEDERAL | B11: 1 | F11: 23.74 | G11: 331.11 | H11: 573.45 | I11: 373.45 | J11: 0 | K11: 0 | L11: =F11+H11+J11 | M11: =SUM(G11,I11,K11) | N11: =M11-L11
A12: CASEMBRAPA | L12: =F12+H12+J12 | M12: =SUM(G12,I12,K12) | N12: =M12-L12
A13: CASSI | B13: 106 | D13: 33 | F13: 28398.98 | G13: 178239.55 | H13: 104095.7 | I13: 45377.24 | J13: 77955.84 | K13: 24775.21 | L13: =F13+H13+J13 | M13: =SUM(G13,I13,K13) | N13: =M13-L13
A14: CENTRO CLINICO GAUCHO | L14: =F14+H14+J14 | M14: =SUM(G14,I14,K14) | N14: =M14-L14
A15: EMBAIXADOR | L15: =F15+H15+J15 | M15: =SUM(G15,I15,K15) | N15: =M15-L15
A16: GEAP | B16: 23 | F16: 8805.24 | G16: 36537.54 | H16: 13104.25 | I16: 7874.28 | J16: 887.92 | K16: 1181.32 | L16: =F16+H16+J16 | M16: =SUM(G16,I16,K16) | N16: =M16-L16
A17: GRATUIDADE | F17: 5000 | G17: 3695 | H17: 0 | I17: 0 | J17: 0 | K17: 0 | L17: =F17+H17+J17 | M17: =SUM(G17,I17,K17) | N17: =M17-L17
A18: IPE | B18: 479 | C18: 201 | D18: 41 | E18: 34 | F18: 563440.48 | G18: 99896.3 | H18: 467905.76 | I18: 647539.13 | J18: 49155.33 | K18: 37808.16 | L18: =F18+H18+J18 | M18: =SUM(G18,I18,K18) | N18: =M18-L18
A19: IPE SEM PIN PAD | L19: =F19+H19+J19 | M19: =SUM(G19,I19,K19) | N19: =M19-L19
A20: IPIRANGA - SAMEISA | L20: =F20+H20+J20 | M20: =SUM(G20,I20,K20) | N20: =M20-L20
A21: PARTICULAR | B21: 50 | C21: 6 | F21: 22149.98 | G21: 49385.02 | H21: 31881.2 | I21: 23571 | J21: 34291.55 | K21: 32294.95 | L21: =F21+H21+J21 | M21: =SUM(G21,I21,K21) | N21: =M21-L21
A22: PETROBRAS | L22: =F22+H22+J22 | M22: =SUM(G22,I22,K22) | N22: =M22-L22
A23: POSTAL SAUDE | L23: =F23+H23+J23 | M23: =SUM(G23,I23,K23) | N23: =M23-L23
A24: SAUDE BRADESCO | F24: 44.83 | G24: 439.88 | H24: 0 | I24: 0 | J24: 494.61 | K24: 375.49 | L24: =F24+H24+J24 | M24: =SUM(G24,I24,K24) | N24: =M24-L24
A25: SAUDE MAIOR | C25: 262 | D25: 11 | E25: 5 | F25: 55196.29 | H25: 170855.6 | J25: 86197.28 | L25: =F25+H25+J25 | M25: 400000 | N25: =M25-L25
A26: SAUDE PAS MEDICINA | L26: =F26+H26+J26 | M26: =G26+I26+K26 | N26: =M26-L26
A27: SOCIOS | B27: 1 | C27: 12 | F27: 4419.35 | H27: 7280.85 | J27: 24802.51 | L27: =F27+H27+J27 | M27: 4460.7 | N27: =M27-L27
A28: SULAMERICA | L28: =F28+H28+J28 | M28: =G28+I28+K28 | N28: =M28-L28
A29: SUS | C29: 2432 | D29: 296 | E29: 198 | H29: 2209883 | L29: =F29+H29+J29 | M29: 2327154.3 | N29: =M29-L29
A30: TRANSPORTADORA FONSECA JUNIOR LTDA - EPP | L30: =F30+H30+J30 | M30: =G30+I30+K30 | N30: =M30-L30
A31: UNIMED | B31: 99 | C31: 131 | D31: 35 | E31: 32 | F31: 1595094.6 | G31: 79677.13 | H31: 222021.68 | I31: 234487.14 | J31: 24216.36 | K31: 48612.72 | L31: =F31+H31+J31 | M31: =SUM(G31,I31,K31) | N31: =M31-L31
A32: TOTAL | B32: =SUM(B6:B31) | C32: =SUM(C6:C31) | D32: =SUM(D6:D31) | E32: =SUM(E6:E31) | F32: =SUM(F6:F31) | G32: =SUM(G6:G31) | H32: =SUM(H6:H31) | I32: =SUM(I6:I31) | ... N32: =SUM(N6:N31)
A34: FEVEREIRO | G34: ="INTERNAÇÕES - "& '[1]intern. diaria convenio'!$D$42 | K34: ="DIÁRIAS - " &'[1]intern. diaria convenio'!$D$88
A35: CONVENIO | B35: Diárias por Leito | F35: MAT / MED | H35: DIARIAS | J35: TAXAS | L35: TOTAL_CUSTO | M35: TOTAL_VENDA | N35: TOTAL
B36: PRIV. | C36: SEMI-P | D36: UTI | E36: UCTI | F36: CUSTO | G36: VENDA | H36: CUSTO | I36: VENDA | J36: CUSTO | K36: VENDA | L36: CUSTO | M36: VENDA | N36: RESULTADO
A37: ACORDO | C37: 50 | E37: 4 | F37: 19777.44 | H37: 32394.31 | J37: 82180.8 | L37: =F37+H37+J37 | M37: 172252.5 | N37: =M37-L37
A38: ACORDO JUDICIAL | L38: =F38+H38+J38 | M38: 4102.5 | N38: =M38-L38
A39: ASSEFAZ | L39: =F39+H39+J39 | M39: =G39+I39+K39 | N39: =M39-L39
A40: C.M.I | C40: 1 | F40: 342.83 | H40: 558.95 | J40: 2361.11 | L40: =F40+H40+J40 | M40: 14 | N40: =M40-L40
A41: CABERGS | B41: 16 | F41: 2618.6 | G41: 28264.23 | H41: 8943.2 | I41: 8605.76 | J41: 22428.25 | K41: 5380.58 | L41: =F41+H41+J41 | M41: =SUM(G41,I41,K41) | N41: =M41-L41
A42: CAIXA ECONOMICA FEDERAL | L42: =F42+H42+J42 | M42: =SUM(G42,I42,K42) | N42: =M42-L42
...

Sheet Acordo Judicial
A1: INTERNAÇÕES HOSPITALARES - ESTUDO CUSTO/RECEITA POR CONVÊNIO - ANO 2024
A3: ACORDO JUDICIAL
D5: INTERNAÇÕES - | G5: 0 | H5: DIÁRIAS - | J5: 0
A6: CONVÊNIO | C6: DIÁRIAS COBRADAS | G6: MAT/MED | I6: DIÁRIAS | K6: TAXAS | M6: TOTAL
C7: PRIV. | D7: SEMI-P | E7: UTI | F7: UCTI | G7: T. CUSTO | H7: T. VENDA | I7: T. CUSTO | J7: T. VENDA | K7: T. CUSTO | L7: T. VENDA | M7: T. CUSTO | N7: T. VENDA | O7: RESULTADO
A8: JANEIRO | C8: =Total!B7 | D8: =Total!C7 | E8: =Total!D7 | F8: =Total!E7 | G8: =Total!F7 | H8: =Total!G7 | I8: =Total!H7 | J8: =Total!I7 | ... O8: =Total!N7
A9: FEVEREIRO | C9: =Total!B38 | D9: =Total!C38 | E9: =Total!D38 | F9: =Total!E38 | G9: =Total!F38 | H9: =Total!G38 | I9: =Total!H38 | J9: =Total!I38 | ... O9: =Total!N38
A10: MARÇO | C10: =Total!B69 | D10: =Total!C69 | E10: =Total!D69 | F10: =Total!E69 | G10: =Total!F69 | H10: =Total!G69 | I10: =Total!H69 | J10: =Total!I69 | ... O10: =Total!N69
A11: ABRIL | C11: =Total!B100 | D11: =Total!C100 | E11: =Total!D100 | F11: =Total!E100 | G11: =Total!F100 | H11: =Total!G100 | I11: =Total!H100 | J11: =Total!I100 | ... O11: =Total!N100
A12: MAIO | C12: =Total!B131 | D12: =Total!C131 | E12: =Total!D131 | F12: =Total!E131 | G12: =Total!F131 | H12: =Total!G131 | I12: =Total!H131 | J12: =Total!I131 | ... O12: =Total!N131
A13: JUNHO | C13: =Total!B162 | D13: =Total!C162 | E13: =Total!D162 | F13: =Total!E162 | G13: =Total!F162 | H13: =Total!G162 | I13: =Total!H162 | J13: =Total!I162 | ... O13: =Total!N162
A14: JULHO | C14: =Total!B193 | D14: =Total!C193 | E14: =Total!D193 | F14: =Total!E193 | G14: =Total!F193 | H14: =Total!G193 | I14: =Total!H193 | J14: =Total!I193 | ... O14: =Total!N193
A15: AGOSTO | C15: =Total!B224 | D15: =Total!C224 | E15: =Total!D224 | F15: =Total!E224 | G15: =Total!F224 | H15: =Total!G224 | I15: =Total!H224 | J15: =Total!I224 | ... O15: =Total!N224
A16: SETEMBRO | C16: =Total!B255 | D16: =Total!C255 | E16: =Total!D255 | F16: =Total!E255 | G16: =Total!F255 | H16: =Total!G255 | I16: =Total!H255 | J16: =Total!I255 | ... O16: =Total!N255
A17: OUTUBRO | C17: =Total!B286 | D17: =Total!C286 | E17: =Total!D286 | F17: =Total!E286 | G17: =Total!F286 | H17: =Total!G286 | I17: =Total!H286 | J17: =Total!I286 | ... O17: =Total!N286
A18: NOVEMBRO | C18: =Total!B317 | D18: =Total!C317 | E18: =Total!D317 | F18: =Total!E317 | G18: =Total!F317 | H18: =Total!G317 | I18: =Total!H317 | J18: =Total!I317 | ... O18: =Total!N317
A19: DEZEMBRO | C19: =Total!B348 | D19: =Total!C348 | E19: =Total!D348 | F19: =Total!E348 | G19: =Total!F348 | H19: =Total!G348 | I19: =Total!H348 | J19: =Total!I348 | ... O19: =Total!N348
A20: Total | C20: =SUM(C8:C19) | D20: =SUM(D8:D19) | E20: =SUM(E8:E19) | F20: =SUM(F8:F19) | G20: =SUM(G8:G19) | H20: =SUM(H8:H19) | I20: =SUM(I8:I19) | J20: =SUM(J8:J19) | ... O20: =SUM(O8:O19)
B24: Dif: | G24: =SUM(C20:E20) | H24: =G24-J5

Sheet Acordo
A1: INTERNAÇÕES HOSPITALARES - ESTUDO CUSTO/RECEITA POR CONVÊNIO - ANO 2024
A3: ACORDO
D5: INTERNAÇÕES - | G5: ='[3]intern. diaria convenio'!$O$4 | H5: DIÁRIAS - | J5: ='[3]intern. diaria convenio'!$O$50
A6: CONVÊNIO | C6: DIÁRIAS COBRADAS | G6: MAT/MED | I6: DIÁRIAS | K6: TAXAS | M6: TOTAL
C7: PRIV. | D7: SEMI-P | E7: UTI | F7: UCTI | G7: T. CUSTO | H7: T. VENDA | I7: T. CUSTO | J7: T. VENDA | K7: T. CUSTO | L7: T. VENDA | M7: T. CUSTO | N7: T. VENDA | O7: RESULTADO
A8: JANEIRO | C8: =Total!B6 | D8: =Total!C6 | E8: =Total!D6 | F8: =Total!E6 | G8: =Total!F6 | H8: =Total!G6 | I8: =Total!H6 | J8: =Total!I6 | ... O8: =Total!N6
A9: FEVEREIRO | C9: =Total!B37 | D9: =Total!C37 | E9: =Total!D37 | F9: =Total!E37 | G9: =Total!F37 | H9: =Total!G37 | I9: =Total!H37 | J9: =Total!I37 | ... O9: =Total!N37
A10: MARÇO | C10: =Total!B68 | D10: =Total!C68 | E10: =Total!D68 | F10: =Total!E68 | G10: =Total!F68 | H10: =Total!G68 | I10: =Total!H68 | J10: =Total!I68 | ... O10: =Total!N68
A11: ABRIL | C11: =Total!B99 | D11: =Total!C99 | E11: =Total!D99 | F11: =Total!E99 | G11: =Total!F99 | H11: =Total!G99 | I11: =Total!H99 | J11: =Total!I99 | ... O11: =Total!N99
A12: MAIO | C12: =Total!B130 | D12: =Total!C130 | E12: =Total!D130 | F12: =Total!E130 | G12: =Total!F130 | H12: =Total!G130 | I12: =Total!H130 | J12: =Total!I130 | ... O12: =Total!N130
A13: JUNHO | C13: =Total!B161 | D13: =Total!C161 | E13: =Total!D161 | F13: =Total!E161 | G13: =Total!F161 | H13: =Total!G161 | I13: =Total!H161 | J13: =Total!I161 | ... O13: =Total!N161
A14: JULHO | C14: =Total!B192 | D14: =Total!C192 | E14: =Total!D192 | F14: =Total!E192 | G14: =Total!F192 | H14: =Total!G192 | I14: =Total!H192 | J14: =Total!I192 | ... O14: =Total!N192
A15: AGOSTO | C15: =Total!B223 | D15: =Total!C223 | E15: =Total!D223 | F15: =Total!E223 | G15: =Total!F223 | H15: =Total!G223 | I15: =Total!H223 | J15: =Total!I223 | ... O15: =Total!N223
A16: SETEMBRO | C16: =Total!B254 | D16: =Total!C254 | E16: =Total!D254 | F16: =Total!E254 | G16: =Total!F254 | H16: =Total!G254 | I16: =Total!H254 | J16: =Total!I254 | ... O16: =Total!N254
A17: OUTUBRO | C17: =Total!B285 | D17: =Total!C285 | E17: =Total!D285 | F17: =Total!E285 | G17: =Total!F285 | H17: =Total!G285 | I17: =Total!H285 | J17: =Total!I285 | ... O17: =Total!N285
A18: NOVEMBRO | C18: =Total!B316 | D18: =Total!C316 | E18: =Total!D316 | F18: =Total!E316 | G18: =Total!F316 | H18: =Total!G316 | I18: =Total!H316 | J18: =Total!I316 | ... O18: =Total!N316
A19: DEZEMBRO | C19: =Total!B347 | D19: =Total!C347 | E19: =Total!D347 | F19: =Total!E347 | G19: =Total!F347 | H19: =Total!G347 | I19: =Total!H347 | J19: =Total!I347 | ... O19: =Total!N347
A20: Total | C20: =SUM(C8:C19) | D20: =SUM(D8:D19) | E20: =SUM(E8:E19) | F20: =SUM(F8:F19) | G20: =SUM(G8:G19) | H20: =SUM(H8:H19) | I20: =SUM(I8:I19) | J20: =SUM(J8:J19) | ... O20: =SUM(O8:O19)
B24: Dif: | G24: =SUM(C20:E20) | H24: =G24-J5

Sheet C.M.I
A1: INTERNAÇÕES HOSPITALARES - ESTUDO CUSTO/RECEITA POR CONVÊNIO - ANO 2024
A3: C.M.I
D5: INTERNAÇÕES - | G5: ='[3]intern. diaria convenio'!$O$9 | H5: DIÁRIAS - | J5: ='[3]intern. diaria convenio'!$O$55
A6: CONVÊNIO | C6: DIÁRIAS COBRADAS | G6: MAT/MED | I6: DIÁRIAS | K6: TAXAS | M6: TOTAL
C7: PRIV. | D7: SEMI-P | E7: UTI | F7: UCTI | G7: T. CUSTO | H7: T. VENDA | I7: T. CUSTO | J7: T. VENDA | K7: T. CUSTO | L7: T. VENDA | M7: T. CUSTO | N7: T. VENDA | O7: RESULTADO
A8: JANEIRO | C8: =Total!B9 | D8: =Total!C9 | E8: =Total!D9 | F8: =Total!E9 | G8: =Total!F9 | H8: =Total!G9 | I8: =Total!H9 | J8: =Total!I9 | ... O8: =Total!N9
A9: FEVEREIRO | C9: =Total!B40 | D9: =Total!C40 | E9: =Total!D40 | F9: =Total!E40 | G9: =Total!F40 | H9: =Total!G40 | I9: =Total!H40 | J9: =Total!I40 | ... O9: =Total!N40
A10: MARÇO | C10: =Total!B71 | D10: =Total!C71 | E10: =Total!D71 | F10: =Total!E71 | G10: =Total!F71 | H10: =Total!G71 | I10: =Total!H71 | J10: =Total!I71 | ... O10: =Total!N71
A11: ABRIL | C11: =Total!B102 | D11: =Total!C102 | E11: =Total!D102 | F11: =Total!E102 | G11: =Total!F102 | H11: =Total!G102 | I11: =Total!H102 | J11: =Total!I102 | ... O11: =Total!N102
A12: MAIO | C12: =Total!B133 | D12: =Total!C133 | E12: =Total!D133 | F12: =Total!E133 | G12: =Total!F133 | H12: =Total!G133 | I12: =Total!H133 | J12: =Total!I133 | ... O12: =Total!N133
A13: JUNHO | C13: =Total!B164 | D13: =Total!C164 | E13: =Total!D164 | F13: =Total!E164 | G13: =Total!F164 | H13: =Total!G164 | I13: =Total!H164 | J13: =Total!I164 | ... O13: =Total!N164
A14: JULHO | C14: =Total!B195 | D14: =Total!C195 | E14: =Total!D195 | F14: =Total!E195 | G14: =Total!F195 | H14: =Total!G195 | I14: =Total!H195 | J14: =Total!I195 | ... O14: =Total!N195
A15: AGOSTO | C15: =Total!B226 | D15: =Total!C226 | E15: =Total!D226 | F15: =Total!E226 | G15: =Total!F226 | H15: =Total!G226 | I15: =Total!H226 | J15: =Total!I226 | ... O15: =Total!N226
A16: SETEMBRO | C16: =Total!B257 | D16: =Total!C257 | E16: =Total!D257 | F16: =Total!E257 | G16: =Total!F257 | H16: =Total!G257 | I16: =Total!H257 | J16: =Total!I257 | ... O16: =Total!N257
A17: OUTUBRO | C17: =Total!B288 | D17: =Total!C288 | E17: =Total!D288 | F17: =Total!E288 | G17: =Total!F288 | H17: =Total!G288 | I17: =Total!H288 | J17: =Total!I288 | ... O17: =Total!N288
A18: NOVEMBRO | C18: =Total!B319 | D18: =Total!C319 | E18: =Total!D319 | F18: =Total!E319 | G18: =Total!F319 | H18: =Total!G319 | I18: =Total!H319 | J18: =Total!I319 | ... O18: =Total!N319
A19: DEZEMBRO | C19: =Total!B350 | D19: =Total!C350 | E19: =Total!D350 | F19: =Total!E350 | G19: =Total!F350 | H19: =Total!G350 | I19: =Total!H350 | J19: =Total!I350 | ... O19: =Total!N350
A20: Total | C20: =SUM(C8:C19) | D20: =SUM(D8:D19) | E20: =SUM(E8:E19) | F20: =SUM(F8:F19) | G20: =SUM(G8:G19) | H20: =SUM(H8:H19) | I20: =SUM(I8:I19) | J20: =SUM(J8:J19) | ... O20: =SUM(O8:O19)

Sheet CABERGS
A1: INTERNAÇÕES HOSPITALARES - ESTUDO CUSTO/RECEITA POR CONVÊNIO - ANO 2024
A3: CABERGS
D5: INTERNAÇÕES - | G5: ='[3]intern. diaria convenio'!$O$10 | H5: DIÁRIAS - | J5: ='[3]intern. diaria convenio'!$O$56
A6: CONVÊNIO | C6: DIÁRIAS COBRADAS | G6: MAT/MED | I6: DIÁRIAS | K6: TAXAS | M6: TOTAL
C7: PRIV. | D7: SEMI-P | E7: UTI | F7: UCTI | G7: T. CUSTO | H7: T. VENDA | I7: T. CUSTO | J7: T. VENDA | K7: T. CUSTO | L7: T. VENDA | M7: T. CUSTO | N7: T. VENDA | O7: RESULTADO
A8: JANEIRO | C8: =Total!B10 | D8: =Total!C10 | E8: =Total!D10 | F8: =Total!E10 | G8: =Total!F10 | H8: =Total!G10 | I8: =Total!H10 | J8: =Total!I10 | ... O8: =Total!N10
A9: FEVEREIRO | C9: =Total!B41 | D9: =Total!C41 | E9: =Total!D41 | F9: =Total!E41 | G9: =Total!F41 | H9: =Total!G41 | I9: =Total!H41 | J9: =Total!I41 | ... O9: =Total!N41
A10: MARÇO | C10: =Total!B72 | D10: =Total!C72 | E10: =Total!D72 | F10: =Total!E72 | G10: =Total!F72 | H10: =Total!G72 | I10: =Total!H72 | J10: =Total!I72 | ... O10: =Total!N72
A11: ABRIL | C11: =Total!B103 | D11: =Total!C103 | E11: =Total!D103 | F11: =Total!E103 | G11: =Total!F103 | H11: =Total!G103 | I11: =Total!H103 | J11: =Total!I103 | ... O11: =Total!N103
A12: MAIO | C12: =Total!B134 | D12: =Total!C134 | E12: =Total!D134 | F12: =Total!E134 | G12: =Total!F134 | H12: =Total!G134 | I12: =Total!H134 | J12: =Total!I134 | ... O12: =Total!N134
A13: JUNHO | C13: =Total!B165 | D13: =Total!C165 | E13: =Total!D165 | F13: =Total!E165 | G13: =Total!F165 | H13: =Total!G165 | I13: =Total!H165 | J13: =Total!I165 | ... O13: =Total!N165
A14: JULHO | C14: =Total!B196 | D14: =Total!C196 | E14: =Total!D196 | F14: =Total!E196 | G14: =Total!F196 | H14: =Total!G196 | I14: =Total!H196 | J14: =Total!I196 | ... O14: =Total!N196
A15: AGOSTO | C15: =Total!B227 | D15: =Total!C227 | E15: =Total!D227 | F15: =Total!E227 | G15: =Total!F227 | H15: =Total!G227 | I15: =Total!H227 | J15: =Total!I227 | ... O15: =Total!N227
A16: SETEMBRO | C16: =Total!B258 | D16: =Total!C258 | E16: =Total!D258 | F16: =Total!E258 | G16: =Total!F258 | H16: =Total!G258 | I16: =Total!H258 | J16: =Total!I258 | ... O16: =Total!N258
A17: OUTUBRO | C17: =Total!B289 | D17: =Total!C289 | E17: =Total!D289 | F17: =Total!E289 | G17: =Total!F289 | H17: =Total!G289 | I17: =Total!H289 | J17: =Total!I289 | ... O17: =Total!N289
A18: NOVEMBRO | C18: =Total!B320 | D18: =Total!C320 | E18: =Total!D320 | F18: =Total!E320 | G18: =Total!F320 | H18: =Total!G320 | I18: =Total!H320 | J18: =Total!I320 | ... O18: =Total!N320
A19: DEZEMBRO | C19: =Total!B351 | D19: =Total!C351 | E19: =Total!D351 | F19: =Total!E351 | G19: =Total!F351 | H19: =Total!G351 | I19: =Total!H351 | J19: =Total!I351 | ... O19: =Total!N351
A20: Total | C20: =SUM(C8:C19) | D20: =SUM(D8:D19) | E20: =SUM(E8:E19) | F20: =SUM(F8:F19) | G20: =SUM(G8:G19) | H20: =SUM(H8:H19) | I20: =SUM(I8:I19) | J20: =SUM(J8:J19) | ... O20: =SUM(O8:O19)
B24: Dif: | G24: =SUM(C20:E20) | H24: =G24-J5

Sheet CAIXA ECONOMICA
A1: INTERNAÇÕES HOSPITALARES - ESTUDO CUSTO/RECEITA POR CONVÊNIO - ANO 2024
A3: CAIXA ECONOMICA FEDERAL
D5: INTERNAÇÕES - | G5: ='[3]intern. diaria convenio'!$O$8 | H5: DIÁRIAS - | J5: ='[3]intern. diaria convenio'!$O$54
A6: CONVÊNIO | C6: DIÁRIAS COBRADAS | G6: MAT/MED | I6: DIÁRIAS | K6: TAXAS | M6: TOTAL
C7: PRIV. | D7: SEMI-P | E7: UTI | F7: UCTI | G7: T. CUSTO | H7: T. VENDA | I7: T. CUSTO | J7: T. VENDA | K7: T. CUSTO | L7: T. VENDA | M7: T. CUSTO | N7: T. VENDA | O7: RESULTADO
A8: JANEIRO | C8: =Total!B11 | D8: =Total!C11 | E8: =Total!D11 | F8: =Total!E11 | G8: =Total!F11 | H8: =Total!G11 | I8: =Total!H11 | J8: =Total!I11 | ... O8: =Total!N11
A9: FEVEREIRO | C9: =Total!B42 | D9: =Total!C42 | E9: =Total!D42 | F9: =Total!E42 | G9: =Total!F12 | H9: =Total!G12 | I9: =Total!H12 | J9: =Total!I12 | K9: =Total!J12 | L9: =Total!K12 | M9: =Total!L12 | N9: =Total!M12 | O9: =Total!N12
A10: MARÇO | C10: =Total!B73 | D10: =Total!C73 | E10: =Total!D73 | F10: =Total!E73 | G10: =Total!F13 | H10: =Total!G13 | I10: =Total!H13 | J10: =Total!I13 | K10: =Total!J13 | L10: =Total!K13 | M10: =Total!L13 | N10: =Total!M13 | O10: =Total!N13
A11: ABRIL | C11: =Total!B104 | D11: =Total!C104 | E11: =Total!D104 | F11: =Total!E104 | G11: =Total!F14 | H11: =Total!G14 | I11: =Total!H14 | J11: =Total!I14 | K11: =Total!J14 | L11: =Total!K14 | M11: =Total!L14 | N11: =Total!M14 | O11: =Total!N14
A12: MAIO | C12: =Total!B135 | D12: =Total!C135 | E12: =Total!D135 | F12: =Total!E135 | G12: =Total!F15 | H12: =Total!G15 | I12: =Total!H15 | J12: =Total!I15 | K12: =Total!J15 | L12: =Total!K15 | M12: =Total!L15 | N12: =Total!M15 | O12: =Total!N15
A13: JUNHO | C13: =Total!B146 | D13: =Total!C146 | E13: =Total!D146 | F13: =Total!E146 | G13: =Total!F16 | H13: =Total!G16 | I13: =Total!H16 | J13: =Total!I16 | K13: =Total!J16 | L13: =Total!K16 | M13: =Total!L16 | N13: =Total!M16 | O13: =Total!N16
A14: JULHO | C14: =Total!B177 | D14: =Total!C177 | E14: =Total!D177 | F14: =Total!E177 | G14: =Total!F17 | H14: =Total!G17 | I14: =Total!H17 | J14: =Total!I17 | K14: =Total!J17 | L14: =Total!K17 | M14: =Total!L17 | N14: =Total!M17 | O14: =Total!N17
A15: AGOSTO | C15: =Total!B208 | D15: =Total!C208 | E15: =Total!D208 | F15: =Total!E208 | G15: =Total!F18 | H15: =Total!G18 | I15: =Total!H18 | J15: =Total!I18 | K15: =Total!J18 | L15: =Total!K18 | M15: =Total!L18 | N15: =Total!M18 | O15: =Total!N18
A16: SETEMBRO | C16: =Total!B239 | D16: =Total!C239 | E16: =Total!D239 | F16: =Total!E239 | G16: =Total!F19 | H16: =Total!G19 | I16: =Total!H19 | J16: =Total!I19 | K16: =Total!J19 | L16: =Total!K19 | M16: =Total!L19 | N16: =Total!M19 | O16: =Total!N19
A17: OUTUBRO | C17: =Total!B270 | D17: =Total!C270 | E17: =Total!D270 | F17: =Total!E270 | G17: =Total!F20 | H17: =Total!G20 | I17: =Total!H20 | J17: =Total!I20 | K17: =Total!J20 | L17: =Total!K20 | M17: =Total!L20 | N17: =Total!M20 | O17: =Total!N20
A18: NOVEMBRO | C18: =Total!B301 | D18: =Total!C301 | E18: =Total!D301 | F18: =Total!E301 | G18: =Total!F21 | H18: =Total!G21 | I18: =Total!H21 | J18: =Total!I21 | K18: =Total!J21 | L18: =Total!K21 | M18: =Total!L21 | N18: =Total!M21 | O18: =Total!N21
A19: DEZEMBRO | C19: =Total!B332 | D19: =Total!C332 | E19: =Total!D332 | F19: =Total!E332 | G19: =Total!F22 | H19: =Total!G22 | I19: =Total!H22 | J19: =Total!I22 | K19: =Total!J22 | L19: =Total!K22 | M19: =Total!L22 | N19: =Total!M22 | O19: =Total!N22
A20: Total | C20: =SUM(C8:C19) | D20: =SUM(D8:D19) | E20: =SUM(E8:E19) | F20: =SUM(F8:F19) | G20: =SUM(G8:G19) | H20: =SUM(H8:H19) | I20: =SUM(I8:I19) | J20: =SUM(J8:J19) | ... O20: =SUM(O8:O19)
B24: Dif: | G24: =SUM(C20:E20) | H24: =G24-J5

Sheet CASSI
A1: INTERNAÇÕES HOSPITALARES - ESTUDO CUSTO/RECEITA POR CONVÊNIO - ANO 2024
A3: CASSI
D5: INTERNAÇÕES - | G5: ='[3]intern. diaria convenio'!$O$12 | H5: DIÁRIAS - | J5: ='[3]intern. diaria convenio'!$O$58
A6: CONVÊNIO | C6: DIÁRIAS COBRADAS | G6: MAT/MED | I6: . | K6: TAXAS | M6: TOTAL
C7: PRIV. | D7: SEMI-P | E7: UTI | F7: UCTI | G7: T. CUSTO | H7: T. VENDA | I7: T. CUSTO | J7: T. VENDA | K7: T. CUSTO | L7: T. VENDA | M7: T. CUSTO | N7: T. VENDA | O7: RESULTADO
A8: JANEIRO | C8: =Total!B13 | D8: =Total!C13 | E8: =Total!D13 | F8: =Total!E13 | G8: =Total!F13 | H8: =Total!G13 | I8: =Total!H13 | J8: =Total!I13 | ... L8: =Total!K13 | M8: =K8+I8+G8 | N8: =Total!M13 | O8: =Total!N13
A9: FEVEREIRO | C9: =Total!B44 | D9: =Total!C44 | E9: =Total!D44 | F9: =Total!E44 | G9: =Total!F44 | H9: =Total!G44 | I9: =Total!H44 | J9: =Total!I44 | ... O9: =Total!N44
A10: MARÇO | C10: =Total!B75 | D10: =Total!C75 | E10: =Total!D75 | F10: =Total!E75 | G10: =Total!F75 | H10: =Total!G75 | I10: =Total!H75 | J10: =Total!I75 | ... O10: =Total!N75
A11: ABRIL | C11: =Total!B106 | D11: =Total!C106 | E11: =Total!D106 | F11: =Total!E106 | G11: =Total!F106 | H11: =Total!G106 | I11: =Total!H106 | J11: =Total!I106 | ... O11: =Total!N106
A12: MAIO | C12: =Total!B137 | D12: =Total!C137 | E12: =Total!D137 | F12: =Total!E137 | G12: =Total!F137 | H12: =Total!G137 | I12: =Total!H137 | J12: =Total!I137 | ... O12: =Total!N137
A13: JUNHO | C13: =Total!B168 | D13: =Total!C168 | E13: =Total!D168 | F13: =Total!E168 | G13: =Total!F168 | H13: =Total!G168 | I13: =Total!H168 | J13: =Total!I168 | ... O13: =Total!N168
A14: JULHO | C14: =Total!B199 | D14: =Total!C199 | E14: =Total!D199 | F14: =Total!E199 | G14: =Total!F199 | H14: =Total!G199 | I14: =Total!H199 | J14: =Total!I199 | ... O14: =Total!N199
A15: AGOSTO | C15: =Total!B230 | D15: =Total!C230 | E15: =Total!D230 | F15: =Total!E230 | G15: =Total!F230 | H15: =Total!G230 | I15: =Total!H230 | J15: =Total!I230 | ... O15: =Total!N230
A16: SETEMBRO | C16: =Total!B261 | D16: =Total!C261 | E16: =Total!D261 | F16: =Total!E261 | G16: =Total!F261 | H16: =Total!G261 | I16: =Total!H261 | J16: =Total!I261 | ... O16: =Total!N261
A17: OUTUBRO | C17: =Total!B292 | D17: =Total!C292 | E17: =Total!D292 | F17: =Total!E292 | G17: =Total!F292 | H17: =Total!G292 | I17: =Total!H292 | J17: =Total!I292 | ... O17: =Total!N292
A18: NOVEMBRO | C18: =Total!B323 | D18: =Total!C323 | E18: =Total!D323 | F18: =Total!E323 | G18: =Total!F323 | H18: =Total!G323 | I18: =Total!H323 | J18: =Total!I323 | ... O18: =Total!N323
A19: DEZEMBRO | C19: =Total!B354 | D19: =Total!C354 | E19: =Total!D354 | F19: =Total!E354 | G19: =Total!F354 | H19: =Total!G354 | I19: =Total!H354 | J19: =Total!I354 | ... O19: =Total!N354
A20: Total | C20: =SUM(C8:C19) | D20: =SUM(D8:D19) | E20: =SUM(E8:E19) | F20: =SUM(F8:F19) | G20: =SUM(G8:G19) | H20: =SUM(H8:H19) | I20: =SUM(I8:I19) | J20: =SUM(J8:J19) | ... O20: =SUM(O8:O19)
B24: Dif: | G24: =SUM(C20:E20) | H24: =G24-J5

Sheet EMBAIXADOR
A1: INTERNAÇÕES HOSPITALARES - ESTUDO CUSTO/RECEITA POR CONVÊNIO - ANO 2024
A3: EMBAIXADOR
D5: INTERNAÇÕES - | G5: ='[3]intern. diaria convenio'!$O$16 | H5: DIÁRIAS - | J5: ='[3]intern. diaria convenio'!$O$62
A6: CONVÊNIO | C6: DIÁRIAS COBRADAS | G6: MAT/MED | I6: DIÁRIAS | K6: TAXAS | M6: TOTAL
C7: PRIV. | D7: SEMI-P | E7: UTI | F7: UCTI | G7: T. CUSTO | H7: T. VENDA | I7: T. CUSTO | J7: T. VENDA | K7: T. CUSTO | L7: T. VENDA | M7: T. CUSTO | N7: T. VENDA | O7: RESULTADO
A8: JANEIRO | C8: =Total!B15 | D8: =Total!C15 | E8: =Total!D15 | F8: =Total!E15 | G8: =Total!F15 | H8: =Total!G15 | I8: =Total!H15 | J8: =Total!I15 | ... O8: =Total!N15
A9: FEVEREIRO | C9: =Total!B46 | D9: =Total!C46 | E9: =Total!D46 | F9: =Total!E46 | G9: =Total!J46 | H9: =Total!G46 | I9: =Total!H46 | J9: =Total!I46 | K9: =Total!J46 | L9: =Total!K46 | M9: =Total!L46 | N9: =Total!M46 | O9: =Total!N46
A10: MARÇO | C10: =Total!B77 | D10: =Total!C77 | E10: =Total!D77 | F10: =Total!E77 | G10: =Total!F77 | H10: =Total!G77 | I10: =Total!H77 | J10: =Total!I77 | ... O10: =Total!N77
A11: ABRIL | C11: =Total!B108 | D11: =Total!C108 | E11: =Total!D108 | F11: =Total!E108 | G11: =Total!F108 | H11: =Total!G108 | I11: =Total!H108 | J11: =Total!I108 | ... O11: =Total!N108
A12: MAIO | C12: =Total!B139 | D12: =Total!C139 | E12: =Total!D139 | F12: =Total!E139 | G12: =Total!F181 | H12: =Total!G139 | I12: =Total!H139 | J12: =Total!I139 | K12: =Total!J139 | L12: =Total!K139 | M12: =Total!L139 | N12: =Total!M139 | O12: =Total!N139
A13: JUNHO | C13: =Total!B170 | D13: =Total!C170 | E13: =Total!D170 | F13: =Total!E170 | G13: =Total!F170 | H13: =Total!G170 | I13: =Total!H170 | J13: =Total!I170 | ... O13: =Total!N170
A14: JULHO | C14: =Total!B201 | D14: =Total!C201 | E14: =Total!D201 | F14: =Total!E201 | G14: =Total!F201 | H14: =Total!G201 | I14: =Total!H201 | J14: =Total!I201 | ... O14: =Total!N201
A15: AGOSTO | C15: =Total!B232 | D15: =Total!C232 | E15: =Total!D232 | F15: =Total!E232 | G15: =Total!F232 | H15: =Total!G232 | I15: =Total!H232 | J15: =Total!I232 | ... O15: =Total!N232
A16: SETEMBRO | C16: =Total!B263 | D16: =Total!C263 | E16: =Total!D263 | F16: =Total!E263 | G16: =Total!F263 | H16: =Total!G263 | I16: =Total!H263 | J16: =Total!I263 | ... O16: =Total!N263
A17: OUTUBRO | C17: =Total!B294 | D17: =Total!C294 | E17: =Total!D294 | F17: =Total!E294 | G17: =Total!F294 | H17: =Total!G294 | I17: =Total!H294 | J17: =Total!I294 | ... O17: =Total!N294
A18: NOVEMBRO | C18: =Total!B325 | D18: =Total!C325 | E18: =Total!D325 | F18: =Total!E325 | G18: =Total!F325 | H18: =Total!G325 | I18: =Total!H325 | J18: =Total!I325 | ... O18: =Total!N325
A19: DEZEMBRO | C19: =Total!B356 | D19: =Total!C356 | E19: =Total!D356 | F19: =Total!E356 | G19: =Total!F356 | H19: =Total!G356 | I19: =Total!H356 | J19: =Total!I356 | ... O19: =Total!N356
A20: Total | C20: =SUM(C8:C19) | D20: =SUM(D8:D19) | E20: =SUM(E8:E19) | F20: =SUM(F8:F19) | G20: =SUM(G8:G19) | H20: =SUM(H8:H19) | I20: =SUM(I8:I19) | J20: =SUM(J8:J19) | ... O20: =SUM(O8:O19)
B24: Dif: | G24: =SUM(C20:E20) | H24: =G24-J5

Sheet GEAP
A1: INTERNAÇÕES HOSPITALARES - ESTUDO CUSTO/RECEITA POR CONVÊNIO - ANO 2024
A3: GEAP
D5: INTERNAÇÕES - | G5: ='[3]intern. diaria convenio'!$O$21 | H5: DIÁRIAS - | J5: ='[3]intern. diaria convenio'!$O$67
A6: CONVÊNIO | C6: DIÁRIAS COBRADAS | G6: MAT/MED | I6: DIÁRIAS | K6: TAXAS | M6: TOTAL
C7: PRIV. | D7: SEMI-P | E7: UTI | F7: UCTI | G7: T. CUSTO | H7: T. VENDA | I7: T. CUSTO | J7: T. VENDA | K7: T. CUSTO | L7: T. VENDA | M7: T. CUSTO | N7: T. VENDA | O7: RESULTADO
A8: JANEIRO | C8: =Total!B16 | D8: =Total!C16 | E8: =Total!D16 | F8: =Total!E16 | G8: =Total!F16 | H8: =Total!G16 | I8: =Total!H16 | J8: =Total!I16 | ... O8: =Total!N16
A9: FEVEREIRO | C9: =Total!B47 | D9: =Total!C47 | E9: =Total!D47 | F9: =Total!E47 | G9: =Total!F47 | H9: =Total!G47 | I9: =Total!H47 | J9: =Total!I47 | ... O9: =Total!N47
A10: MARÇO | C10: =Total!B78 | D10: =Total!C78 | E10: =Total!D78 | F10: =Total!E78 | G10: =Total!F78 | H10: =Total!G78 | I10: =Total!H78 | J10: =Total!I78 | ... O10: =Total!N78
A11: ABRIL | C11: =Total!B109 | D11: =Total!C109 | E11: =Total!D109 | F11: =Total!E109 | G11: =Total!F109 | H11: =Total!G109 | I11: =Total!H109 | J11: =Total!I109 | ... O11: =Total!N109
A12: MAIO | C12: =Total!B140 | D12: =Total!C140 | E12: =Total!D140 | F12: =Total!E140 | G12: =Total!F140 | H12: =Total!G140 | I12: =Total!H140 | J12: =Total!I140 | ... O12: =Total!N140
A13: JUNHO | C13: =Total!B171 | D13: =Total!C171 | E13: =Total!D171 | F13: =Total!E171 | G13: =Total!F171 | H13: =Total!G171 | I13: =Total!H171 | J13: =Total!I171 | ... O13: =Total!N171
A14: JULHO | C14: =Total!B202 | D14: =Total!C202 | E14: =Total!D202 | F14: =Total!E202 | G14: =Total!F202 | H14: =Total!G202 | I14: =Total!H202 | J14: =Total!I202 | ... O14: =Total!N202
A15: AGOSTO | C15: =Total!B233 | D15: =Total!C233 | E15: =Total!D233 | F15: =Total!E233 | G15: =Total!F233 | H15: =Total!G233 | I15: =Total!H233 | J15: =Total!I233 | ... O15: =Total!N233
A16: SETEMBRO | C16: =Total!B264 | D16: =Total!C264 | E16: =Total!D264 | F16: =Total!E264 | G16: =Total!F264 | H16: =Total!G264 | I16: =Total!H264 | J16: =Total!I264 | ... O16: =Total!N264
A17: OUTUBRO | C17: =Total!B295 | D17: =Total!C295 | E17: =Total!D295 | F17: =Total!E295 | G17: =Total!F295 | H17: =Total!G295 | I17: =Total!H295 | J17: =Total!I295 | ... O17: =Total!N295
A18: NOVEMBRO | C18: =Total!B326 | D18: =Total!C326 | E18: =Total!D326 | F18: =Total!E326 | G18: =Total!F326 | H18: =Total!G326 | I18: =Total!H326 | J18: =Total!I326 | ... O18: =Total!N326
A19: DEZEMBRO | C19: =Total!B357 | D19: =Total!C357 | E19: =Total!D357 | F19: =Total!E357 | G19: =Total!F357 | H19: =Total!G357 | I19: =Total!H357 | J19: =Total!I357 | ... O19: =Total!N357
A20: Total | C20: =SUM(C8:C19) | D20: =SUM(D8:D19) | E20: =SUM(E8:E19) | F20: =SUM(F8:F19) | G20: =SUM(G8:G19) | H20: =SUM(H8:H19) | I20: =SUM(I8:I19) | J20: =SUM(J8:J19) | ... O20: =SUM(O8:O19)
B24: Dif: | G24: =SUM(C20:E20) | H24: =G24-J5

Sheet IPE
A1: INTERNAÇÕES HOSPITALARES - ESTUDO CUSTO/RECEITA POR CONVÊNIO - ANO 2024
A3: IPE
D5: INTERNAÇÕES - | G5: ='[3]intern. diaria convenio'!$O$24 | H5: DIÁRIAS - | J5: ='[3]intern. diaria convenio'!$O$70
A6: CONVÊNIO | C6: DIÁRIAS COBRADAS | G6: MAT/MED | I6: DIÁRIAS | K6: TAXAS | M6: TOTAL
C7: PRIV. | D7: SEMI-P | E7: UTI | F7: UCTI | G7: T. CUSTO | H7: T. VENDA | I7: T. CUSTO | J7: T. VENDA | K7: T. CUSTO | L7: T. VENDA | M7: T. CUSTO | N7: T. VENDA | O7: RESULTADO
A8: JANEIRO | C8: =Total!B18 | D8: =Total!C18 | E8: =Total!D18 | F8: =Total!E18 | G8: =Total!F18 | H8: =Total!G18 | I8: =Total!H18 | J8: =Total!I18 | ... O8: =Total!N18
A9: FEVEREIRO | C9: =Total!B49 | D9: =Total!C49 | E9: =Total!D49 | F9: =Total!E49 | G9: =Total!F49 | H9: =Total!G49 | I9: =Total!H49 | J9: =Total!I49 | ... O9: =Total!N49
A10: MARÇO | C10: =Total!B80 | D10: =Total!C80 | E10: =Total!D80 | F10: =Total!E80 | G10: =Total!F80 | H10: =Total!G80 | I10: =Total!H80 | J10: =Total!I80 | ... O10: =Total!N80
A11: ABRIL | C11: =Total!B111 | D11: =Total!C111 | E11: =Total!D111 | F11: =Total!E111 | G11: =Total!F111 | H11: =Total!G111 | I11: =Total!H111 | J11: =Total!I111 | ... O11: =Total!N111
A12: MAIO | C12: =Total!B142 | D12: =Total!C142 | E12: =Total!D142 | F12: =Total!E142 | G12: =Total!F142 | H12: =Total!G142 | I12: =Total!H142 | J12: =Total!I142 | ... O12: =Total!N142
A13: JUNHO | C13: =Total!B173 | D13: =Total!C173 | E13: =Total!D173 | F13: =Total!E173 | G13: =Total!F173 | H13: =Total!G173 | I13: =Total!H173 | J13: =Total!I173 | ... O13: =Total!N173
A14: JULHO | C14: =Total!B204 | D14: =Total!C204 | E14: =Total!D204 | F14: =Total!E204 | G14: =Total!F204 | H14: =Total!G204 | I14: =Total!H204 | J14: =Total!I204 | ... O14: =Total!N204
A15: AGOSTO | C15: =Total!B235 | D15: =Total!C235 | E15: =Total!D235 | F15: =Total!E235 | G15: =Total!F235 | H15: =Total!G235 | I15: =Total!H235 | J15: =Total!I235 | ... O15: =Total!N235
A16: SETEMBRO | C16: =Total!B266 | D16: =Total!C266 | E16: =Total!D266 | F16: =Total!E266 | G16: =Total!F266 | H16: =Total!G266 | I16: =Total!H266 | J16: =Total!I266 | ... O16: =Total!N266
A17: OUTUBRO | C17: =Total!B297 | D17: =Total!C297 | E17: =Total!D297 | F17: =Total!E297 | G17: =Total!F297 | H17: =Total!G297 | I17: =Total!H297 | J17: =Total!I297 | ... O17: =Total!N297
A18: NOVEMBRO | C18: =Total!B328 | D18: =Total!C328 | E18: =Total!D328 | F18: =Total!E328 | G18: =Total!F328 | H18: =Total!G328 | I18: =Total!H328 | J18: =Total!I328 | ... O18: =Total!N328
A19: DEZEMBRO | C19: 489 | D19: 146 | E19: 20 | F19: 18 | G19: =Total!F359 | H19: =Total!G359 | I19: =Total!H359 | J19: =Total!I359 | K19: =Total!J359 | L19: =Total!K359 | M19: =Total!L359 | N19: =Total!M359 | O19: =Total!N359
A20: Total | C20: =SUM(C8:C19) | D20: =SUM(D8:D19) | E20: =SUM(E8:E19) | F20: =SUM(F8:F19) | G20: =SUM(G8:G19) | H20: =SUM(H8:H19) | I20: =SUM(I8:I19) | J20: =SUM(J8:J19) | ... O20: =SUM(O8:O19)
B24: Dif: | G24: =SUM(C20:E20) | H24: =G24-J5

Sheet IPE SEM PIN PAD
A1: INTERNAÇÕES HOSPITALARES - ESTUDO CUSTO/RECEITA POR CONVÊNIO - ANO 2023
A3: IPE SEM PIN PAD
D5: INTERNAÇÕES - | H5: DIÁRIAS -
A6: CONVÊNIO | C6: DIÁRIAS COBRADAS | G6: MAT/MED | I6: DIÁRIAS | K6: TAXAS | M6: TOTAL
C7: PRIV. | D7: SEMI-P | E7: UTI | F7: UCTI | G7: T. CUSTO | H7: T. VENDA | I7: T. CUSTO | J7: T. VENDA | K7: T. CUSTO | L7: T. VENDA | M7: T. CUSTO | N7: T. VENDA | O7: RESULTADO
A8: JANEIRO | C8: =Total!B19 | D8: =Total!C19 | E8: =Total!D19 | F8: =Total!E19 | G8: =Total!F19 | H8: =Total!G19 | I8: =Total!H19 | J8: =Total!I19 | ... O8: =Total!N19
A9: FEVEREIRO | C9: =Total!B50 | D9: =Total!C50 | E9: =Total!D50 | F9: =Total!E50 | G9: =Total!F50 | H9: =Total!G50 | I9: =Total!H50 | J9: =Total!I50 | ... O9: =Total!N50
A10: MARÇO | C10: =Total!B81 | D10: =Total!C81 | E10: =Total!D81 | F10: =Total!E81 | G10: =Total!F81 | H10: =Total!G81 | I10: =Total!H81 | J10: =Total!I81 | ... O10: =Total!N81
A11: ABRIL | C11: =Total!B112 | D11: =Total!C112 | E11: =Total!D112 | F11: =Total!E112 | G11: =Total!F112 | H11: =Total!G112 | I11: =Total!H112 | J11: =Total!I112 | ... O11: =Total!N112
A12: MAIO | C12: =Total!B143 | D12: =Total!C143 | E12: =Total!D143 | F12: =Total!E143 | G12: =Total!F143 | H12: =Total!G143 | I12: =Total!H143 | J12: =Total!I143 | ... O12: =Total!N143
A13: JUNHO | C13: =Total!B174 | D13: =Total!C174 | E13: =Total!D174 | F13: =Total!E174 | G13: =Total!F174 | H13: =Total!G174 | I13: =Total!H174 | J13: =Total!I174 | ... O13: =Total!N174
A14: JULHO | C14: =Total!B205 | D14: =Total!C205 | E14: =Total!D205 | F14: =Total!E205 | G14: =Total!F205 | H14: =Total!G205 | I14: =Total!H205 | J14: =Total!I205 | ... O14: =Total!N205
A15: AGOSTO | C15: =Total!B236 | D15: =Total!C236 | E15: =Total!D236 | F15: =Total!E236 | G15: =Total!F236 | H15: =Total!G236 | I15: =Total!H236 | J15: =Total!I236 | ... O15: =Total!N236
A16: SETEMBRO | C16: =Total!B267 | D16: =Total!C267 | E16: =Total!D267 | F16: =Total!E267 | G16: =Total!F267 | H16: =Total!G267 | I16: =Total!H267 | J16: =Total!I267 | ... O16: =Total!N267
A17: OUTUBRO | C17: =Total!B298 | D17: =Total!C298 | E17: =Total!D298 | F17: =Total!E298 | G17: =Total!F298 | H17: =Total!G298 | I17: =Total!H298 | J17: =Total!I298 | ... O17: =Total!N298
A18: NOVEMBRO | C18: =Total!B329 | D18: =Total!C329 | E18: =Total!D329 | F18: =Total!E329 | G18: =Total!F329 | H18: =Total!G329 | I18: =Total!H329 | J18: =Total!I329 | ... O18: =Total!N329
A19: DEZEMBRO | C19: =Total!B360 | D19: =Total!C360 | E19: =Total!D360 | F19: =Total!E360 | G19: =Total!F360 | H19: =Total!G360 | I19: =Total!H360 | J19: =Total!I360 | ... O19: =Total!N360
A20: Total | C20: =SUM(C8:C19) | D20: =SUM(D8:D19) | E20: =SUM(E8:E19) | F20: =SUM(F8:F19) | G20: =SUM(G8:G19) | H20: =SUM(H8:H19) | I20: =SUM(I8:I19) | J20: =SUM(J8:J19) | ... O20: =SUM(O8:O19)

Sheet PARTICULAR
A1: INTERNAÇÕES HOSPITALARES - ESTUDO CUSTO/RECEITA POR CONVÊNIO - ANO 2024
A3: PARTICULAR
D5: INTERNAÇÕES - | G5: ='[3]intern. diaria convenio'!$O$29 | H5: DIÁRIAS - | J5: ='[3]intern. diaria convenio'!$O$75
A6: CONVÊNIO | C6: DIÁRIAS COBRADAS | G6: MAT/MED | I6: DIÁRIAS | K6: TAXAS | M6: TOTAL
C7: PRIV. | D7: SEMI-P | E7: UTI | F7: UCTI | G7: T. CUSTO | H7: T. VENDA | I7: T. CUSTO | J7: T. VENDA | K7: T. CUSTO | L7: T. VENDA | M7: T. CUSTO | N7: T. VENDA | O7: RESULTADO
A8: JANEIRO | C8: =Total!B21 | D8: =Total!C21 | E8: =Total!D21 | F8: =Total!E21 | G8: =Total!F21 | H8: =Total!G21 | I8: =Total!H21 | J8: =Total!I21 | ... O8: =Total!N21
A9: FEVEREIRO | C9: =Total!B52 | D9: =Total!C52 | E9: =Total!D52 | F9: =Total!E52 | G9: =Total!F52 | H9: =Total!G52 | I9: =Total!H52 | J9: =Total!I52 | ... O9: =Total!N52
A10: MARÇO | C10: =Total!B83 | D10: =Total!C83 | E10: =Total!D83 | F10: =Total!E83 | G10: =Total!F83 | H10: =Total!G83 | I10: =Total!H83 | J10: =Total!I83 | ... O10: =Total!N83
A11: ABRIL | C11: =Total!B114 | D11: =Total!C114 | E11: =Total!D114 | F11: =Total!E114 | G11: =Total!F114 | H11: =Total!G114 | I11: =Total!H114 | J11: =Total!I114 | ... O11: =Total!N114
A12: MAIO | C12: =Total!B145 | D12: =Total!C145 | E12: =Total!D145 | F12: =Total!E145 | G12: =Total!F145 | H12: =Total!G145 | I12: =Total!H145 | J12: =Total!I145 | ... O12: =Total!N145
A13: JUNHO | C13: =Total!B176 | D13: =Total!C176 | E13: =Total!D176 | F13: =Total!E176 | G13: =Total!F176 | H13: =Total!G176 | I13: =Total!H176 | J13: =Total!I176 | ... O13: =Total!N176
A14: JULHO | C14: =Total!B207 | D14: =Total!C207 | E14: =Total!D207 | F14: =Total!E207 | G14: =Total!F207 | H14: =Total!G207 | I14: =Total!H207 | J14: =Total!I207 | ... O14: =Total!N207
A15: AGOSTO | C15: =Total!B238 | D15: =Total!C238 | E15: =Total!D238 | F15: =Total!E238 | G15: =Total!F238 | H15: =Total!G238 | I15: =Total!H238 | J15: =Total!I238 | ... O15: =Total!N238
A16: SETEMBRO | C16: =Total!B269 | D16: =Total!C269 | E16: =Total!D269 | F16: =Total!E269 | G16: =Total!F269 | H16: =Total!G269 | I16: =Total!H269 | J16: =Total!I269 | ... O16: =Total!N269
A17: OUTUBRO | C17: =Total!B300 | D17: =Total!C300 | E17: =Total!D300 | F17: =Total!E300 | G17: =Total!F300 | H17: =Total!G300 | I17: =Total!H300 | J17: =Total!I300 | ... O17: =Total!N300
A18: NOVEMBRO | C18: =Total!B331 | D18: =Total!C331 | E18: =Total!D331 | F18: =Total!E331 | G18: =Total!F331 | H18: =Total!G331 | I18: =Total!H331 | J18: =Total!I331 | ... O18: =Total!N331
A19: DEZEMBRO | C19: =Total!B362 | D19: =Total!C362 | E19: =Total!D362 | F19: =Total!E362 | G19: =Total!F362 | H19: =Total!G362 | I19: =Total!H362 | J19: =Total!I362 | ... O19: =Total!N362
A20: Total | C20: =SUM(C8:C19) | D20: =SUM(D8:D19) | E20: =SUM(E8:E19) | F20: =SUM(F8:F19) | G20: =SUM(G8:G19) | H20: =SUM(H8:H19) | I20: =SUM(I8:I19) | J20: =SUM(J8:J19) | ... O20: =SUM(O8:O19)
B24: Dif: | G24: =SUM(C20:E20) | H24: =G24-J5

Sheet SAUDE BRADESCO
A1: INTERNAÇÕES HOSPITALARES - ESTUDO CUSTO/RECEITA POR CONVÊNIO - ANO 2024
A3: SAUDE BRADESCO
D5: INTERNAÇÕES - | G5: ='[3]intern. diaria convenio'!$O$32 | H5: DIÁRIAS - | J5: ='[3]intern. diaria convenio'!$O$78
A6: CONVÊNIO | C6: DIÁRIAS COBRADAS | G6: MAT/MED | I6: DIÁRIAS | K6: TAXAS | M6: TOTAL
C7: PRIV. | D7: SEMI-P | E7: UTI | F7: UCTI | G7: T. CUSTO | H7: T. VENDA | I7: T. CUSTO | J7: T. VENDA | K7: T. CUSTO | L7: T. VENDA | M7: T. CUSTO | N7: T. VENDA | O7: RESULTADO
A8: JANEIRO | C8: =Total!B24 | D8: =Total!C24 | E8: =Total!D24 | F8: =Total!E24 | G8: =Total!F24 | H8: =Total!G24 | I8: =Total!H24 | J8: =Total!I24 | ... O8: =Total!N24
A9: FEVEREIRO | C9: =Total!B55 | D9: =Total!C55 | E9: =Total!D55 | F9: =Total!E55 | G9: =Total!F55 | H9: =Total!G55 | I9: =Total!H55 | J9: =Total!I55 | ... O9: =Total!N55
A10: MARÇO | C10: =Total!B86 | D10: =Total!C86 | E10: =Total!D86 | F10: =Total!E86 | G10: =Total!F86 | H10: =Total!G86 | I10: =Total!H86 | J10: =Total!I86 | ... O10: =Total!N86
A11: ABRIL | C11: =Total!B117 | D11: =Total!C117 | E11: =Total!D117 | F11: =Total!E117 | G11: =Total!F117 | H11: =Total!G117 | I11: =Total!H117 | J11: =Total!I117 | ... O11: =Total!N117
A12: MAIO | C12: =Total!B148 | D12: =Total!C148 | E12: =Total!D148 | F12: =Total!E148 | G12: =Total!F148 | H12: =Total!G148 | I12: =Total!H148 | J12: =Total!I148 | ... O12: =Total!N148
A13: JUNHO | C13: =Total!B179 | D13: =Total!C179 | E13: =Total!D179 | F13: =Total!E179 | G13: =Total!F179 | H13: =Total!G179 | I13: =Total!H179 | J13: =Total!I179 | ... O13: =Total!N179
A14: JULHO | C14: =Total!B210 | D14: =Total!C210 | E14: =Total!D210 | F14: =Total!E210 | G14: =Total!F210 | H14: =Total!G210 | I14: =Total!H210 | J14: =Total!I210 | ... O14: =Total!N210
A15: AGOSTO | C15: =Total!B241 | D15: =Total!C241 | E15: =Total!D241 | F15: =Total!E241 | G15: =Total!F241 | H15: =Total!G241 | I15: =Total!H241 | J15: =Total!I241 | ... O15: =Total!N241
A16: SETEMBRO | C16: =Total!B272 | D16: =Total!C272 | E16: =Total!D272 | F16: =Total!E272 | G16: =Total!F272 | H16: =Total!G272 | I16: =Total!H272 | J16: =Total!I272 | ... O16: =Total!N272
A17: OUTUBRO | C17: =Total!B303 | D17: =Total!C303 | E17: =Total!D303 | F17: =Total!E303 | G17: =Total!F303 | H17: =Total!G303 | I17: =Total!H303 | J17: =Total!I303 | ... O17: =Total!N303
A18: NOVEMBRO | C18: =Total!B334 | D18: =Total!C334 | E18: =Total!D334 | F18: =Total!E334 | G18: =Total!F334 | H18: =Total!G334 | I18: =Total!H334 | J18: =Total!I334 | ... O18: =Total!N334
A19: DEZEMBRO | C19: =Total!B365 | D19: =Total!C365 | E19: =Total!D365 | F19: =Total!E365 | G19: =Total!F365 | H19: =Total!G365 | I19: =Total!H365 | J19: =Total!I365 | ... O19: =Total!N365
A20: Total | C20: =SUM(C8:C19) | D20: =SUM(D8:D19) | E20: =SUM(E8:E19) | F20: =SUM(F8:F19) | G20: =SUM(G8:G19) | H20: =SUM(H8:H19) | I20: =SUM(I8:I19) | J20: =SUM(J8:J19) | ... O20: =SUM(O8:O19)
B24: Dif: | G24: =SUM(C20:E20) | H24: =G24-J5

Sheet SAUDE MAIOR
A1: INTERNAÇÕES HOSPITALARES - ESTUDO CUSTO/RECEITA POR CONVÊNIO - ANO 2024 | R1: INTERNAÇÕES HOSPITALARES - ESTUDO CUSTO/RECEITA POR CONVÊNIO - ANO 2023
A3: SAUDE MAIOR | R3: TOTAL SAUDE MAIOR (AMBULATORIAL + INTERNADOS)
D5: INTERNAÇÕES - | G5: ='[3]intern. diaria convenio'!$O$33 | H5: DIÁRIAS - | J5: ='[5]intern. diaria convenio'!$O$79 | U5: INTERNAÇÕES - | X5: =G5 | Y5: DIÁRIAS - | AA5: =J5
A6: CONVÊNIO | C6: DIÁRIAS COBRADAS | G6: MAT/MED | I6: DIÁRIAS | K6: TAXAS | M6: TOTAL | R6: CONVÊNIO | T6: DIÁRIAS COBRADAS | X6: MAT/MED | Z6: DIÁRIAS | AB6: TAXAS | AD6: TOTAL
C7: PRIV. | D7: SEMI-P | E7: UTI | F7: UCTI | G7: T. CUSTO | H7: T. VENDA | I7: T. CUSTO | J7: T. VENDA | K7: T. CUSTO | L7: T. VENDA | M7: T. CUSTO | N7: T. VENDA | O7: RESULTADO | T7: PRIV. | U7: SEMI-P | V7: UTI | W7: UCTI | X7: T. CUSTO | Y7: T. VENDA | Z7: T. CUSTO | AA7: T. VENDA | AB7: T. CUSTO | AC7: T. VENDA | AD7: T. CUSTO | AE7: T. VENDA | AF7: RESULTADO
A8: JANEIRO | C8: =Total!B25 | D8: =Total!C25 | E8: =Total!D25 | F8: =Total!E25 | G8: =Total!F25 | H8: =Total!G25 | I8: =Total!H25 | J8: =Total!I25 | ... O8: =Total!N25 | R8: JANEIRO | T8: =C8 | U8: =D8 | V8: =E8 | W8: =F8 | X8: =G8+'[6]SAUDE MAIOR'!C8 | Y8: =H8+'[6]SAUDE MAIOR'!$D8 | Z8: =I8 | AA8: =J8 | AB8: =K8+'[6]SAUDE MAIOR'!E8 | AC8: =L8+'[6]SAUDE MAIOR'!$F8 | AD8: =X8+Z8+AB8 | AE8: =370000+'[6]SAUDE MAIOR'!$H8 | AF8: =AE8-AD8
A9: FEVEREIRO | C9: =Total!B56 | D9: =Total!C56 | E9: =Total!D56 | F9: =Total!E56 | G9: =Total!F56 | H9: =Total!G56 | I9: =Total!H56 | J9: =Total!I56 | ... O9: =Total!N56 | R9: FEVEREIRO | T9: =C9 | U9: =D9 | V9: =E9 | W9: =F9 | X9: =G9+'[6]SAUDE MAIOR'!C9 | Y9: =H9+'[6]SAUDE MAIOR'!$D9 | Z9: =I9 | AA9: =J9 | AB9: =K9+'[6]SAUDE MAIOR'!E9 | AC9: =L9+'[6]SAUDE MAIOR'!$F9 | AD9: =X9+Z9+AB9 | AE9: =300000+'[6]SAUDE MAIOR'!$H9 | AF9: =AE9-AD9
A10: MARÇO | C10: =Total!B87 | D10: =Total!C87 | E10: =Total!D87 | F10: =Total!E87 | G10: =Total!F87 | H10: =Total!G87 | I10: =Total!H87 | J10: =Total!I87 | ... O10: =Total!N87 | R10: MARÇO | T10: =C10 | U10: =D10 | V10: =E10 | W10: =F10 | X10: =G10+'[6]SAUDE MAIOR'!C10 | Y10: =H10+'[6]SAUDE MAIOR'!$D10 | Z10: =I10 | AA10: =J10 | AB10: =K10+'[6]SAUDE MAIOR'!E10 | AC10: =L10+'[6]SAUDE MAIOR'!$F10 | AD10: =X10+Z10+AB10 | AE10: =300000+'[6]SAUDE MAIOR'!$H10 | AF10: =AE10-AD10
A11: ABRIL | C11: =Total!B118 | D11: =Total!C118 | E11: =Total!D118 | F11: =Total!E118 | G11: =Total!F118 | H11: =Total!G118 | I11: =Total!H118 | J11: =Total!I118 | ... O11: =Total!N118 | R11: ABRIL | T11: =C11 | U11: =D11 | V11: =E11 | W11: =F11 | X11: =G11+'[6]SAUDE MAIOR'!C11 | Y11: =H11+'[6]SAUDE MAIOR'!$D11 | Z11: =I11 | AA11: =J11 | AB11: =K11+'[6]SAUDE MAIOR'!E11 | AC11: =L11+'[6]SAUDE MAIOR'!$F11 | AD11: =X11+Z11+AB11 | AE11: =300000+'[6]SAUDE MAIOR'!$H11 | AF11: =AE11-AD11
A12: MAIO | C12: =Total!B149 | D12: =Total!C149 | E12: =Total!D149 | F12: =Total!E149 | G12: =Total!F149 | H12: =Total!G149 | I12: =Total!H149 | J12: =Total!I149 | ... O12: =Total!N149 | R12: MAIO | T12: =C12 | U12: =D12 | V12: =E12 | W12: =F12 | X12: =G12+'[6]SAUDE MAIOR'!C12 | Y12: =H12+'[6]SAUDE MAIOR'!$D12 | Z12: =I12 | AA12: =J12 | AB12: =K12+'[6]SAUDE MAIOR'!E12 | AC12: =L12+'[6]SAUDE MAIOR'!$F12 | AD12: =X12+Z12+AB12 | AE12: =300000+'[6]SAUDE MAIOR'!$H12 | AF12: =AE12-AD12
A13: JUNHO | C13: =Total!B180 | D13: =Total!C180 | E13: =Total!D180 | F13: =Total!E180 | G13: =Total!F180 | H13: =Total!G180 | I13: =Total!H180 | J13: =Total!I180 | ... O13: =Total!N180 | R13: JUNHO | T13: =C13 | U13: =D13 | V13: =E13 | W13: =F13 | X13: =G13+'[6]SAUDE MAIOR'!C13 | Y13: =H13+'[6]SAUDE MAIOR'!$D13 | Z13: =I13 | AA13: =J13 | AB13: =K13+'[6]SAUDE MAIOR'!E13 | AC13: =L13+'[6]SAUDE MAIOR'!$F13 | AD13: =X13+Z13+AB13 | AE13: =300000+'[6]SAUDE MAIOR'!$H13 | AF13: =AE13-AD13
A14: JULHO | C14: =Total!B211 | D14: =Total!C211 | E14: =Total!D211 | F14: =Total!E211 | G14: =Total!F211 | H14: =Total!G211 | I14: =Total!H211 | J14: =Total!I211 | ... O14: =Total!N211 | R14: JULHO | T14: =C14 | U14: =D14 | V14: =E14 | W14: =F14 | X14: =G14+'[6]SAUDE MAIOR'!C14 | Y14: =H14+'[6]SAUDE MAIOR'!$D14 | Z14: =I14 | AA14: =J14 | AB14: =K14+'[6]SAUDE MAIOR'!E14 | AC14: =L14+'[6]SAUDE MAIOR'!$F14 | AD14: =X14+Z14+AB14 | AE14: =300000+'[6]SAUDE MAIOR'!$H14 | AF14: =AE14-AD14
A15: AGOSTO | C15: =Total!B242 | D15: =Total!C242 | E15: =Total!D242 | F15: =Total!E242 | G15: =Total!F242 | H15: =Total!G242 | I15: =Total!H242 | J15: =Total!I242 | ... O15: =Total!N242 | R15: AGOSTO | T15: =C15 | U15: =D15 | V15: =E15 | W15: =F15 | X15: =G15+'[6]SAUDE MAIOR'!C15 | Y15: =H15+'[6]SAUDE MAIOR'!$D15 | Z15: =I15 | AA15: =J15 | AB15: =K15+'[6]SAUDE MAIOR'!E15 | AC15: =L15+'[6]SAUDE MAIOR'!$F15 | AD15: =X15+Z15+AB15 | AE15: =300000+'[6]SAUDE MAIOR'!$H15 | AF15: =AE15-AD15
A16: SETEMBRO | C16: =Total!B273 | D16: =Total!C273 | E16: =Total!D273 | F16: =Total!E273 | G16: =Total!F273 | H16: =Total!G273 | I16: =Total!H273 | J16: =Total!I273 | ... O16: =Total!N273 | R16: SETEMBRO | T16: =C16 | U16: =D16 | V16: =E16 | W16: =F16 | X16: =G16+'[6]SAUDE MAIOR'!C16 | Y16: =H16+'[6]SAUDE MAIOR'!$D16 | Z16: =I16 | AA16: =J16 | AB16: =K16+'[6]SAUDE MAIOR'!E16 | AC16: =L16+'[6]SAUDE MAIOR'!$F16 | AD16: =X16+Z16+AB16 | AE16: =300000+'[6]SAUDE MAIOR'!$H16 | AF16: =AE16-AD16
A17: OUTUBRO | C17: =Total!B304 | D17: =Total!C304 | E17: =Total!D304 | F17: =Total!E304 | G17: =Total!F304 | H17: =Total!G304 | I17: =Total!H304 | J17: =Total!I304 | ... O17: =Total!N304 | R17: OUTUBRO | T17: =C17 | U17: =D17 | V17: =E17 | W17: =F17 | X17: =G17+'[6]SAUDE MAIOR'!C17 | Y17: =H17+'[6]SAUDE MAIOR'!$D17 | Z17: =I17 | AA17: =J17 | AB17: =K17+'[6]SAUDE MAIOR'!E17 | AC17: =L17+'[6]SAUDE MAIOR'!$F17 | AD17: =X17+Z17+AB17 | AE17: =300000+'[6]SAUDE MAIOR'!$H17 | AF17: =AE17-AD17
A18: NOVEMBRO | C18: =Total!B335 | D18: =Total!C335 | E18: =Total!D335 | F18: =Total!E335 | G18: =Total!F335 | H18: =Total!G335 | I18: =Total!H335 | J18: =Total!I335 | ... O18: =Total!N335 | R18: NOVEMBRO | T18: =C18 | U18: =D18 | V18: =E18 | W18: =F18 | X18: =G18+'[6]SAUDE MAIOR'!C18 | Y18: =H18+'[6]SAUDE MAIOR'!$D18 | Z18: =I18 | AA18: =J18 | AB18: =K18+'[6]SAUDE MAIOR'!E18 | AC18: =L18+'[6]SAUDE MAIOR'!$F18 | AD18: =X18+Z18+AB18 | AE18: =300000+'[6]SAUDE MAIOR'!$H18 | AF18: =AE18-AD18
A19: DEZEMBRO | C19: =Total!B366 | D19: =Total!C366 | E19: =Total!D366 | F19: =Total!E366 | G19: =Total!F366 | H19: =Total!G366 | I19: =Total!H366 | J19: =Total!I366 | ... O19: =Total!N366 | R19: DEZEMBRO | T19: =C19 | U19: =D19 | V19: =E19 | W19: =F19 | X19: =G19+'[6]SAUDE MAIOR'!C19 | Y19: =H19+'[6]SAUDE MAIOR'!$D19 | Z19: =I19 | AA19: =J19 | AB19: =K19+'[6]SAUDE MAIOR'!E19 | AC19: =L19+'[6]SAUDE MAIOR'!$F19 | AD19: =X19+Z19+AB19 | AE19: =300000+'[6]SAUDE MAIOR'!$H19 | AF19: =AE19-AD19
A20: Total | C20: =SUM(C8:C19) | D20: =SUM(D8:D19) | E20: =SUM(E8:E19) | F20: =SUM(F8:F19) | G20: =SUM(G8:G19) | H20: =SUM(H8:H19) | I20: =SUM(I8:I19) | J20: =SUM(J8:J19) | ... O20: =SUM(O8:O19) | R20: Total | T20: 54 | U20: 1139 | V20: 176 | W20: 0 | X20: =SUM(X8:X19) | Y20: =SUM(Y8:Y19) | Z20: =SUM(Z8:Z19) | AA20: =SUM(AA8:AA19) | AB20: 107358.29 | AC20: =SUM(AC8:AC19) | AD20: =SUM(AD8:AD19) | AE20: =SUM(AE8:AE19) | AF20: =AE20-AD20
G23: SAUDE MAIOR INTERNADO - Janeiro 2024 a Dezembro 2024 | X23: TOTAL SAUDE MAIOR (AMBULATORIO/INTERNADO) - Janeiro 2023 a Dezembro 2023
G24: MAT/MED | I24: DIÁRIAS | K24: TAXAS | M24: TOTAL | X24: MAT/MED | Z24: DIÁRIAS | AB24: TAXAS | AD24: TOTAL
G25: T. CUSTO | H25: T. VENDA | I25: T. CUSTO | J25: T. VENDA | K25: T. CUSTO | L25: T. VENDA | M25: T. CUSTO | N25: T. VENDA | O25: RESULTADO | X25: T. CUSTO | Y25: T. VENDA | Z25: T. CUSTO | AA25: T. VENDA | AB25: T. CUSTO | AC25: T. VENDA | AD25: T. CUSTO | AE25: T. VENDA | AF25: RESULTADO
G26: =G20 | H26: =H20 | I26: =I20 | J26: =J20 | K26: =K20 | L26: =L20 | M26: =M20 | N26: =N20 | O26: =O20 | X26: =X20 | Y26: =Y20 | Z26: =Z20 | AA26: =AA20 | AB26: =AB20 | AC26: =AC20 | AD26: =AD20 | AE26: =AE20 | AF26: =AF20
M27: =M20 | N27: =H20+J20+L20 | O27: =N27-M26 | AD27: =AD20 | AE27: =Y20+AA20+AC20 | AF27: =AE27-AD26

Sheet SOCIOS
A1: INTERNAÇÕES HOSPITALARES - ESTUDO CUSTO/RECEITA POR CONVÊNIO - ANO 2024
A3: SOCIOS
D5: INTERNAÇÕES - | G5: ='[3]intern. diaria convenio'!$O$35 | H5: DIÁRIAS - | J5: ='[3]intern. diaria convenio'!$O$81
A6: CONVÊNIO | C6: DIÁRIAS COBRADAS | G6: MAT/MED | I6: DIÁRIAS | K6: TAXAS | M6: TOTAL
C7: PRIV. | D7: SEMI-P | E7: UTI | F7: UCTI | G7: T. CUSTO | H7: T. VENDA | I7: T. CUSTO | J7: T. VENDA | K7: T. CUSTO | L7: T. VENDA | M7: T. CUSTO | N7: T. VENDA | O7: RESULTADO
A8: JANEIRO | C8: =Total!B27 | D8: =Total!C27 | E8: =Total!D27 | F8: =Total!E27 | G8: =Total!F27 | H8: =Total!G27 | I8: =Total!H27 | J8: =Total!I27 | ... O8: =Total!N27
A9: FEVEREIRO | C9: =Total!B58 | D9: =Total!C58 | E9: =Total!D58 | F9: =Total!E58 | G9: =Total!F58 | H9: =Total!G58 | I9: =Total!H58 | J9: =Total!I58 | ... O9: =Total!N58
A10: MARÇO | C10: =Total!B89 | D10: =Total!C89 | E10: =Total!D89 | F10: =Total!E89 | G10: =Total!F89 | H10: =Total!G89 | I10: =Total!H89 | J10: =Total!I89 | ... O10: =Total!N89
A11: ABRIL | C11: =Total!B120 | D11: =Total!C120 | E11: =Total!D120 | F11: =Total!E120 | G11: =Total!F120 | H11: =Total!G120 | I11: =Total!H120 | J11: =Total!I120 | ... O11: =Total!N120
A12: MAIO | C12: =Total!B151 | D12: =Total!C151 | E12: =Total!D151 | F12: =Total!E151 | G12: =Total!F151 | H12: =Total!G151 | I12: =Total!H151 | J12: =Total!I151 | ... O12: =Total!N151
A13: JUNHO | C13: =Total!B182 | D13: =Total!C182 | E13: =Total!D182 | F13: =Total!E182 | G13: =Total!F182 | H13: =Total!G182 | I13: =Total!H182 | J13: =Total!I182 | ... O13: =Total!N182
A14: JULHO | C14: =Total!B213 | D14: =Total!C213 | E14: =Total!D213 | F14: =Total!E213 | G14: =Total!F213 | H14: =Total!G213 | I14: =Total!H213 | J14: =Total!I213 | ... O14: =Total!N213
A15: AGOSTO | C15: =Total!B244 | D15: =Total!C244 | E15: =Total!D244 | F15: =Total!E244 | G15: =Total!F244 | H15: =Total!G244 | I15: =Total!H244 | J15: =Total!I244 | ... O15: =Total!N244
A16: SETEMBRO | C16: =Total!B275 | D16: =Total!C275 | E16: =Total!D275 | F16: =Total!E275 | G16: =Total!F275 | H16: =Total!G275 | I16: =Total!H275 | J16: =Total!I275 | ... O16: =Total!N275
A17: OUTUBRO | C17: =Total!B306 | D17: =Total!C306 | E17: =Total!D306 | F17: =Total!E306 | G17: =Total!F306 | H17: =Total!G306 | I17: =Total!H306 | J17: =Total!I306 | ... O17: =Total!N306
A18: NOVEMBRO | C18: =Total!B337 | D18: =Total!C337 | E18: =Total!D337 | F18: =Total!E337 | G18: =Total!F337 | H18: =Total!G337 | I18: =Total!H337 | J18: =Total!I337 | ... O18: =Total!N337
A19: DEZEMBRO | C19: =Total!B368 | D19: =Total!C368 | E19: =Total!D368 | F19: =Total!E368 | G19: =Total!F368 | H19: =Total!G368 | I19: =Total!H368 | J19: =Total!I368 | ... O19: =Total!N368
A20: Total | C20: =SUM(C8:C19) | D20: =SUM(D8:D19) | E20: =SUM(E8:E19) | F20: =SUM(F8:F19) | G20: =SUM(G8:G19) | H20: =SUM(H8:H19) | I20: =SUM(I8:I19) | J20: =SUM(J8:J19) | ... O20: =SUM(O8:O19)
B24: Dif: | G24: =SUM(C20:E20) | H24: =G24-J5

Sheet SULAMERICA
A1: INTERNAÇÕES HOSPITALARES - ESTUDO CUSTO/RECEITA POR CONVÊNIO - ANO 2024
A3: SULAMERICA
D5: INTERNAÇÕES - | G5: ='[3]intern. diaria convenio'!$O$36 | H5: DIÁRIAS - | J5: ='[3]intern. diaria convenio'!$O$82
A6: CONVÊNIO | C6: DIÁRIAS COBRADAS | G6: MAT/MED | I6: DIÁRIAS | K6: TAXAS | M6: TOTAL
C7: PRIV. | D7: SEMI-P | E7: UTI | F7: UCTI | G7: T. CUSTO | H7: T. VENDA | I7: T. CUSTO | J7: T. VENDA | K7: T. CUSTO | L7: T. VENDA | M7: T. CUSTO | N7: T. VENDA | O7: RESULTADO
A8: JANEIRO | C8: =Total!B28 | D8: =Total!C28 | E8: =Total!D28 | F8: =Total!E28 | G8: =Total!F28 | H8: =Total!G28 | I8: =Total!H28 | J8: =Total!I28 | ... O8: =Total!N28
A9: FEVEREIRO | C9: =Total!B59 | D9: =Total!C59 | E9: =Total!D59 | F9: =Total!E59 | G9: =Total!F59 | H9: =Total!G59 | I9: =Total!H59 | J9: =Total!I59 | ... O9: =Total!N59
A10: MARÇO | C10: =Total!B90 | D10: =Total!C90 | E10: =Total!D90 | F10: =Total!E90 | G10: =Total!F90 | H10: =Total!G90 | I10: =Total!H90 | J10: =Total!I90 | ... O10: =Total!N90
A11: ABRIL | C11: =Total!B121 | D11: =Total!C121 | E11: =Total!D121 | F11: =Total!E121 | G11: =Total!F121 | H11: =Total!G121 | I11: =Total!H121 | J11: =Total!I121 | ... O11: =Total!N121
A12: MAIO | C12: =Total!B152 | D12: =Total!C152 | E12: =Total!D152 | F12: =Total!E152 | G12: =Total!F152 | H12: =Total!G152 | I12: =Total!H152 | J12: =Total!I152 | ... O12: =Total!N152
A13: JUNHO | C13: =Total!B183 | D13: =Total!C183 | E13: =Total!D183 | F13: =Total!E183 | G13: =Total!F183 | H13: =Total!G183 | I13: =Total!H183 | J13: =Total!I183 | ... O13: =Total!N183
A14: JULHO | C14: =Total!B214 | D14: =Total!C214 | E14: =Total!D214 | F14: =Total!E214 | G14: =Total!F214 | H14: =Total!G214 | I14: =Total!H214 | J14: =Total!I214 | ... O14: =Total!N214
A15: AGOSTO | C15: =Total!B245 | D15: =Total!C245 | E15: =Total!D245 | F15: =Total!E245 | G15: =Total!F245 | H15: =Total!G245 | I15: =Total!H245 | J15: =Total!I245 | ... O15: =Total!N245
A16: SETEMBRO | C16: =Total!B276 | D16: =Total!C276 | E16: =Total!D276 | F16: =Total!E276 | G16: =Total!F276 | H16: =Total!G276 | I16: =Total!H276 | J16: =Total!I276 | ... O16: =Total!N276
A17: OUTUBRO | C17: =Total!B307 | D17: =Total!C307 | E17: =Total!D307 | F17: =Total!E307 | G17: =Total!F307 | H17: =Total!G307 | I17: =Total!H307 | J17: =Total!I307 | ... O17: =Total!N307
A18: NOVEMBRO | C18: =Total!B338 | D18: =Total!C338 | E18: =Total!D338 | F18: =Total!E338 | G18: =Total!F338 | H18: =Total!G338 | I18: =Total!H338 | J18: =Total!I338 | ... O18: =Total!N338
A19: DEZEMBRO | C19: =Total!B369 | D19: =Total!C369 | E19: =Total!D369 | F19: =Total!E369 | G19: =Total!F369 | H19: =Total!G369 | I19: =Total!H369 | J19: =Total!I369 | ... O19: =Total!N369
A20: Total | C20: =SUM(C8:C19) | D20: =SUM(D8:D19) | E20: =SUM(E8:E19) | F20: =SUM(F8:F19) | G20: =SUM(G8:G19) | H20: =SUM(H8:H19) | I20: =SUM(I8:I19) | J20: =SUM(J8:J19) | ... O20: =SUM(O8:O19)
B24: Dif: | G24: =SUM(C20:E20) | H24: =G24-J5

Sheet SUS
A1: INTERNAÇÕES HOSPITALARES - ESTUDO CUSTO/RECEITA POR CONVÊNIO - ANO 2024
A3: SUS
D5: INTERNAÇÕES - | G5: ='[3]intern. diaria convenio'!$O$37 | H5: DIÁRIAS - | J5: ='[3]intern. diaria convenio'!$O$83
A6: CONVÊNIO | C6: DIÁRIAS COBRADAS | G6: MAT/MED | I6: DIÁRIAS | K6: TAXAS | M6: TOTAL
C7: PRIV. | D7: ENF | E7: UTI | F7: UCTI | G7: T. CUSTO | H7: T. VENDA | I7: T. CUSTO | J7: T. VENDA | K7: T. CUSTO | L7: T. VENDA | M7: T. CUSTO | N7: T. VENDA | O7: RESULTADO
A8: JANEIRO | C8: =Total!B29 | D8: =Total!C29 | E8: =Total!D29 | F8: =Total!E29 | G8: =Total!F29 | H8: =Total!G29 | I8: =Total!H29 | J8: =Total!I29 | ... O8: =Total!N29
A9: FEVEREIRO | C9: =Total!B60 | D9: =Total!C60 | E9: =Total!D60 | F9: =Total!E60 | G9: =Total!F60 | H9: =Total!G60 | I9: =Total!H60 | J9: =Total!I60 | ... O9: =Total!N60
A10: MARÇO | C10: =Total!B91 | D10: =Total!C91 | E10: =Total!D91 | F10: =Total!E91 | G10: =Total!F91 | H10: =Total!G91 | I10: =Total!H91 | J10: =Total!I91 | ... O10: =Total!N91
A11: ABRIL | C11: =Total!B122 | D11: =Total!C122 | E11: =Total!D122 | F11: =Total!E122 | G11: =Total!F122 | H11: =Total!G122 | I11: =Total!H122 | J11: =Total!I122 | ... O11: =Total!N122
A12: MAIO | C12: =Total!B153 | D12: =Total!C153 | E12: =Total!D153 | F12: =Total!E153 | G12: =Total!F153 | H12: =Total!G153 | I12: =Total!H153 | J12: =Total!I153 | ... O12: =Total!N153
A13: JUNHO | C13: =Total!B184 | D13: =Total!C184 | E13: =Total!D184 | F13: =Total!E184 | G13: =Total!F184 | H13: =Total!G184 | I13: =Total!H184 | J13: =Total!I184 | ... O13: =Total!N184
A14: JULHO | C14: =Total!B215 | D14: =Total!C215 | E14: =Total!D215 | F14: =Total!E215 | G14: =Total!F215 | H14: =Total!G215 | I14: =Total!H215 | J14: =Total!I215 | ... O14: =Total!N215
A15: AGOSTO | C15: =Total!B246 | D15: =Total!C246 | E15: =Total!D246 | F15: =Total!E246 | G15: =Total!F246 | H15: =Total!G246 | I15: =Total!H246 | J15: =Total!I246 | ... O15: =Total!N246
A16: SETEMBRO | C16: =Total!B277 | D16: =Total!C277 | E16: =Total!D277 | F16: =Total!E277 | G16: =Total!F277 | H16: =Total!G277 | I16: =Total!H277 | J16: =Total!I277 | ... O16: =Total!N277
A17: OUTUBRO | C17: =Total!B308 | D17: =Total!C308 | E17: =Total!D308 | F17: =Total!E308 | G17: =Total!F308 | H17: =Total!G308 | I17: =Total!H308 | J17: =Total!I308 | ... O17: =Total!N308
A18: NOVEMBRO | C18: =Total!B339 | D18: =Total!C339 | E18: =Total!D339 | F18: =Total!E339 | G18: =Total!F339 | H18: =Total!G339 | I18: =Total!H339 | J18: =Total!I339 | ... O18: =Total!N339
A19: DEZEMBRO | C19: =Total!B370 | D19: =Total!C370 | E19: =Total!D370 | F19: =Total!E370 | G19: =Total!F370 | H19: =Total!G370 | I19: =Total!H370 | J19: =Total!I370 | ... O19: =Total!N370
A20: Total | C20: =SUM(C8:C19) | D20: =SUM(D8:D19) | E20: =SUM(E8:E19) | F20: =SUM(F8:F19) | G20: =SUM(G8:G19) | H20: =SUM(H8:H19) | I20: =SUM(I8:I19) | J20: =SUM(J8:J19) | ... O20: =SUM(O8:O19)
J23: 14794149

Sheet UNIMED
A1: INTERNAÇÕES HOSPITALARES - ESTUDO CUSTO/RECEITA POR CONVÊNIO - ANO 2024
A3: UNIMED
D5: INTERNAÇÕES - | G5: ='[3]intern. diaria convenio'!$O$41 | H5: DIÁRIAS - | J5: ='[3]intern. diaria convenio'!$O$87
A6: CONVÊNIO | C6: DIÁRIAS COBRADAS | G6: MAT/MED | I6: DIÁRIAS | K6: TAXAS | M6: TOTAL
C7: PRIV. | D7: SEMI-P | E7: UTI | F7: UCTI | G7: T. CUSTO | H7: T. VENDA | I7: T. CUSTO | J7: T. VENDA | K7: T. CUSTO | L7: T. VENDA | M7: T. CUSTO | N7: T. VENDA | O7: RESULTADO | U7: ACORDO
A8: JANEIRO | C8: =Total!B31 | D8: =Total!C31 | E8: =Total!D31 | F8: =Total!E31 | G8: =Total!F31 | H8: =Total!G31 | I8: =Total!H31 | J8: =Total!I31 | ... O8: =Total!N31 | U8: C.M.I
A9: FEVEREIRO | C9: =Total!B62 | D9: =Total!C62 | E9: =Total!D62 | F9: =Total!E62 | G9: =Total!F62 | H9: =Total!G62 | I9: =Total!H62 | J9: =Total!I62 | ... O9: =Total!N62 | U9: CABERGS
A10: MARÇO | C10: =Total!B93 | D10: =Total!C93 | E10: =Total!D93 | F10: =Total!E93 | G10: =Total!F93 | H10: =Total!G93 | I10: =Total!H93 | J10: =Total!I93 | ... O10: =Total!N93 | U10: CAIXA ECONOMICA
A11: ABRIL | C11: =Total!B124 | D11: =Total!C124 | E11: =Total!D124 | F11: =Total!E124 | G11: =Total!F124 | H11: =Total!G124 | I11: =Total!H124 | J11: =Total!I124 | ... O11: =Total!N124 | U11: CASSI
A12: MAIO | C12: =Total!B155 | D12: =Total!C155 | E12: =Total!D155 | F12: =Total!E155 | G12: =Total!F155 | H12: =Total!G155 | I12: =Total!H155 | J12: =Total!I155 | ... O12: =Total!N155 | U12: EMBAIXADOR
A13: JUNHO | C13: =Total!B186 | D13: =Total!C186 | E13: =Total!D186 | F13: =Total!E186 | G13: =Total!F186 | H13: =Total!G186 | I13: =Total!H186 | J13: =Total!I186 | ... O13: =Total!N186 | U13: GEAP
A14: JULHO | C14: =Total!B217 | D14: =Total!C217 | E14: =Total!D217 | F14: =Total!E217 | G14: =Total!F217 | H14: =Total!G217 | I14: =Total!H217 | J14: =Total!I217 | ... O14: =Total!N217 | U14: IPE
A15: AGOSTO | C15: =Total!B248 | D15: =Total!C248 | E15: =Total!D248 | F15: =Total!E248 | G15: =Total!F248 | H15: =Total!G248 | I15: =Total!H248 | J15: =Total!I248 | ... O15: =Total!N248 | U15: IPE SEM PIN PAD
A16: SETEMBRO | C16: =Total!B279 | D16: =Total!C279 | E16: =Total!D279 | F16: =Total!E279 | G16: =Total!F279 | H16: =Total!G279 | I16: =Total!H279 | J16: =Total!I279 | ... O16: =Total!N279 | U16: PARTICULAR
